Workbook

Sheet Items
A1: # | B1: Nom | C1: Qualité | D1: Effet | E1: Stacking | F1: Tags | G1: Puissance relative | H1: Chance dans la table de sa qualité | I1: Chance par petit coffre | J1: Valeur à 5:00 (points) | K1: Ratio à la cible
A2: 1 | B2: Lentille aiguisée | C2: Commun | D2: +10 % de chance de critique | E2: L | F2: Crit | G2: =INDEX(Drops!$E$14:$E$17,MATCH(C2,Drops!$A$14:$A$17,0)) -> 1 | H2: =INDEX(Drops!$C$14:$C$17,MATCH(C2,Drops!$A$14:$A$17,0)) -> 0.058823529 | I2: =INDEX(Drops!$D$14:$D$17,MATCH(C2,Drops!$A$14:$A$17,0)) -> 0.035294118 | J2: =Audit!I2 -> 9.5238095 | K2: =Audit!L2 -> 0.95238095
A3: 2 | B3: Sablier fêlé | C3: Commun | D3: +18 % de vitesse de recharge des sorts | E3: L (plancher de recharge 25 %) | F3: Recharge | G3: =INDEX(Drops!$E$14:$E$17,MATCH(C3,Drops!$A$14:$A$17,0)) -> 1 | H3: =INDEX(Drops!$C$14:$C$17,MATCH(C3,Drops!$A$14:$A$17,0)) -> 0.058823529 | I3: =INDEX(Drops!$D$14:$D$17,MATCH(C3,Drops!$A$14:$A$17,0)) -> 0.035294118 | J3: =Audit!I3 -> 10.216216 | K3: =Audit!L3 -> 1.0216216
A4: 3 | B4: Antidote | C4: Commun | D4: Dégâts de brûlure et de poison subis -40 % | E4: H | F4: Survie | G4: =INDEX(Drops!$E$14:$E$17,MATCH(C4,Drops!$A$14:$A$17,0)) -> 1 | H4: =INDEX(Drops!$C$14:$C$17,MATCH(C4,Drops!$A$14:$A$17,0)) -> 0.058823529 | I4: =INDEX(Drops!$D$14:$D$17,MATCH(C4,Drops!$A$14:$A$17,0)) -> 0.035294118 | J4: =Audit!I4 -> 11.111111 | K4: =Audit!L4 -> 1.1111111
A5: 4 | B5: Botte rapiécée | C5: Commun | D5: +5 % de vitesse de déplacement (plafond global +10 % pour tous les items) | E5: L plafonné | F5: Mobilité | G5: =INDEX(Drops!$E$14:$E$17,MATCH(C5,Drops!$A$14:$A$17,0)) -> 1 | H5: =INDEX(Drops!$C$14:$C$17,MATCH(C5,Drops!$A$14:$A$17,0)) -> 0.058823529 | I5: =INDEX(Drops!$D$14:$D$17,MATCH(C5,Drops!$A$14:$A$17,0)) -> 0.035294118 | J5: =Audit!I5 -> 10 | K5: =Audit!L5 -> 1
A6: 5 | B6: Pierre à aiguiser | C6: Commun | D6: +10 % de dégâts | E6: L | F6: Dégâts | G6: =INDEX(Drops!$E$14:$E$17,MATCH(C6,Drops!$A$14:$A$17,0)) -> 1 | H6: =INDEX(Drops!$C$14:$C$17,MATCH(C6,Drops!$A$14:$A$17,0)) -> 0.058823529 | I6: =INDEX(Drops!$D$14:$D$17,MATCH(C6,Drops!$A$14:$A$17,0)) -> 0.035294118 | J6: =Audit!I6 -> 10 | K6: =Audit!L6 -> 1
A7: 6 | B7: Bague de vigueur | C7: Commun | D7: +10 % de PV max (minimum +15 PV) | E7: L | F7: Survie | G7: =INDEX(Drops!$E$14:$E$17,MATCH(C7,Drops!$A$14:$A$17,0)) -> 1 | H7: =INDEX(Drops!$C$14:$C$17,MATCH(C7,Drops!$A$14:$A$17,0)) -> 0.058823529 | I7: =INDEX(Drops!$D$14:$D$17,MATCH(C7,Drops!$A$14:$A$17,0)) -> 0.035294118 | J7: =Audit!I7 -> 10 | K7: =Audit!L7 -> 1
A8: 7 | B8: Amulette de cuir | C8: Commun | D8: +10 d'armure (réduction = armure / (armure + 100)) | E8: L | F8: Survie | G8: =INDEX(Drops!$E$14:$E$17,MATCH(C8,Drops!$A$14:$A$17,0)) -> 1 | H8: =INDEX(Drops!$C$14:$C$17,MATCH(C8,Drops!$A$14:$A$17,0)) -> 0.058823529 | I8: =INDEX(Drops!$D$14:$D$17,MATCH(C8,Drops!$A$14:$A$17,0)) -> 0.035294118 | J8: =Audit!I8 -> 10 | K8: =Audit!L8 -> 1
A9: 8 | B9: Aimant de poche | C9: Commun | D9: Rayon de ramassage +40 % et XP gagnée +12 % | E9: L | F9: Or, Progression | G9: =INDEX(Drops!$E$14:$E$17,MATCH(C9,Drops!$A$14:$A$17,0)) -> 1 | H9: =INDEX(Drops!$C$14:$C$17,MATCH(C9,Drops!$A$14:$A$17,0)) -> 0.058823529 | I9: =INDEX(Drops!$D$14:$D$17,MATCH(C9,Drops!$A$14:$A$17,0)) -> 0.035294118 | J9: =Audit!I9 -> 10.2 | K9: =Audit!L9 -> 1.02
A10: 9 | B10: Sifflet de chasse | C10: Commun | D10: +22 % de vitesse d'attaque (sort 1) | E10: L (plafond ×3) | F10: Auto | G10: =INDEX(Drops!$E$14:$E$17,MATCH(C10,Drops!$A$14:$A$17,0)) -> 1 | H10: =INDEX(Drops!$C$14:$C$17,MATCH(C10,Drops!$A$14:$A$17,0)) -> 0.058823529 | I10: =INDEX(Drops!$D$14:$D$17,MATCH(C10,Drops!$A$14:$A$17,0)) -> 0.035294118 | J10: =Audit!I10 -> 9.5135135 | K10: =Audit!L10 -> 0.95135135
A11: 10 | B11: Étincelle | C11: Commun | D11: Proc 18 % : brûlure (100 % du coup sur 3 s) | E11: L (proba) | F11: Feu | G11: =INDEX(Drops!$E$14:$E$17,MATCH(C11,Drops!$A$14:$A$17,0)) -> 1 | H11: =INDEX(Drops!$C$14:$C$17,MATCH(C11,Drops!$A$14:$A$17,0)) -> 0.058823529 | I11: =INDEX(Drops!$D$14:$D$17,MATCH(C11,Drops!$A$14:$A$17,0)) -> 0.035294118 | J11: =Audit!I11 -> 10.08 | K11: =Audit!L11 -> 1.008
A12: 11 | B12: Flocon | C12: Commun | D12: Proc 22 % : ralentissement de 30 % pendant 1,5 s | E12: L (proba) | F12: Givre | G12: =INDEX(Drops!$E$14:$E$17,MATCH(C12,Drops!$A$14:$A$17,0)) -> 1 | H12: =INDEX(Drops!$C$14:$C$17,MATCH(C12,Drops!$A$14:$A$17,0)) -> 0.058823529 | I12: =INDEX(Drops!$D$14:$D$17,MATCH(C12,Drops!$A$14:$A$17,0)) -> 0.035294118 | J12: =Audit!I12 -> 9.856 | K12: =Audit!L12 -> 0.9856
A13: 12 | B13: Fiole verte | C13: Commun | D13: Proc 18 % : poison (1 cumul : 20 % du coup/s pendant 4 s) | E13: L (proba) | F13: Poison | G13: =INDEX(Drops!$E$14:$E$17,MATCH(C13,Drops!$A$14:$A$17,0)) -> 1 | H13: =INDEX(Drops!$C$14:$C$17,MATCH(C13,Drops!$A$14:$A$17,0)) -> 0.058823529 | I13: =INDEX(Drops!$D$14:$D$17,MATCH(C13,Drops!$A$14:$A$17,0)) -> 0.035294118 | J13: =Audit!I13 -> 10.08 | K13: =Audit!L13 -> 1.008
... A51: 50 | B51: Dé pipé | C51: Légendaire | D51: +3 de Chance (relance du d100, on garde le meilleur) et le premier petit coffre de chaque étage est au moins Peu commun | E51: L | F51: Chance | G51: =INDEX(Drops!$E$14:$E$17,MATCH(C51,Drops!$A$14:$A$17,0)) -> 12 | H51: =INDEX(Drops!$C$14:$C$17,MATCH(C51,Drops!$A$14:$A$17,0)) -> 0.16666667 | I51: =INDEX(Drops!$D$14:$D$17,MATCH(C51,Drops!$A$14:$A$17,0)) -> 0.0016666667 | J51: =Audit!I51 -> 125.63669 | K51: =Audit!L51 -> 1.0469724

Sheet Audit
A1: # | B1: Item | C1: Qualité | D1: p1 | E1: p2 | F1: p3 | G1: Signification des paramètres | H1: Valeur à 2:30 | I1: Valeur à 5:00 | J1: Valeur à 7:30 | K1: Cible (points) | L1: Ratio à 5:00 | M1: Dérive 7:30 / 2:30 | N1: Verdict
A2: 1 | B2: Lentille aiguisée | C2: Commun | D2: 0.1 | E2: 2 | G2: p1 = chance de crit ajoutée ; p2 = multiplicateur de crit | H2: =100*((1+(Modèle!$C$14+$D2)*($E2-1))/(1+Modèle!$C$14*(Modèle!$C$15-1))-1) -> 9.5238095 | I2: =100*((1+(Modèle!$D$14+$D2)*($E2-1))/(1+Modèle!$D$14*(Modèle!$D$15-1))-1) -> 9.5238095 | J2: =100*((1+(Modèle!$E$14+$D2)*($E2-1))/(1+Modèle!$E$14*(Modèle!$E$15-1))-1) -> 9.5238095 | K2: =Modèle!$D$2*INDEX(Drops!$E$14:$E$17,MATCH(C2,Drops!$A$14:$A$17,0)) -> 10 | L2: =I2/K2 -> 0.95238095 | M2: =J2/H2 -> 1 | N2: =IF(ABS(L2-1)>0.2,IF(L2<0.8,"Faible","Fort"),IF(OR(M2<0.67,M2>1.5),"Dérive","OK")) -> OK
A3: 2 | B3: Sablier fêlé | C3: Commun | D3: 0.18 | G3: p1 = vitesse de recharge ajoutée | H3: =100*$D3*Modèle!$C$9 -> 10.216216 | I3: =100*$D3*Modèle!$D$9 -> 10.216216 | J3: =100*$D3*Modèle!$E$9 -> 10.216216 | K3: =Modèle!$D$2*INDEX(Drops!$E$14:$E$17,MATCH(C3,Drops!$A$14:$A$17,0)) -> 10 | L3: =I3/K3 -> 1.0216216 | M3: =J3/H3 -> 1 | N3: =IF(ABS(L3-1)>0.2,IF(L3<0.8,"Faible","Fort"),IF(OR(M3<0.67,M3>1.5),"Dérive","OK")) -> OK
A4: 3 | B4: Antidote | C4: Commun | D4: 0.4 | G4: p1 = réduction des dégâts sur la durée | H4: =100*(1/(1-Modèle!$C$34*$D4)-1) -> 11.111111 | I4: =100*(1/(1-Modèle!$D$34*$D4)-1) -> 11.111111 | J4: =100*(1/(1-Modèle!$E$34*$D4)-1) -> 11.111111 | K4: =Modèle!$D$2*INDEX(Drops!$E$14:$E$17,MATCH(C4,Drops!$A$14:$A$17,0)) -> 10 | L4: =I4/K4 -> 1.1111111 | M4: =J4/H4 -> 1 | N4: =IF(ABS(L4-1)>0.2,IF(L4<0.8,"Faible","Fort"),IF(OR(M4<0.67,M4>1.5),"Dérive","OK")) -> OK
A5: 4 | B5: Botte rapiécée | C5: Commun | D5: 0.05 | G5: p1 = vitesse de déplacement ajoutée | H5: =100*$D5*Modèle!$C$36 -> 10 | I5: =100*$D5*Modèle!$D$36 -> 10 | J5: =100*$D5*Modèle!$E$36 -> 10 | K5: =Modèle!$D$2*INDEX(Drops!$E$14:$E$17,MATCH(C5,Drops!$A$14:$A$17,0)) -> 10 | L5: =I5/K5 -> 1 | M5: =J5/H5 -> 1 | N5: =IF(ABS(L5-1)>0.2,IF(L5<0.8,"Faible","Fort"),IF(OR(M5<0.67,M5>1.5),"Dérive","OK")) -> OK
A6: 5 | B6: Pierre à aiguiser | C6: Commun | D6: 0.1 | G6: p1 = bonus de dégâts | H6: =100*$D6 -> 10 | I6: =100*$D6 -> 10 | J6: =100*$D6 -> 10 | K6: =Modèle!$D$2*INDEX(Drops!$E$14:$E$17,MATCH(C6,Drops!$A$14:$A$17,0)) -> 10 | L6: =I6/K6 -> 1 | M6: =J6/H6 -> 1 | N6: =IF(ABS(L6-1)>0.2,IF(L6<0.8,"Faible","Fort"),IF(OR(M6<0.67,M6>1.5),"Dérive","OK")) -> OK
A7: 6 | B7: Bague de vigueur | C7: Commun | D7: 0.1 | G7: p1 = bonus de PV max | H7: =100*$D7 -> 10 | I7: =100*$D7 -> 10 | J7: =100*$D7 -> 10 | K7: =Modèle!$D$2*INDEX(Drops!$E$14:$E$17,MATCH(C7,Drops!$A$14:$A$17,0)) -> 10 | L7: =I7/K7 -> 1 | M7: =J7/H7 -> 1 | N7: =IF(ABS(L7-1)>0.2,IF(L7<0.8,"Faible","Fort"),IF(OR(M7<0.67,M7>1.5),"Dérive","OK")) -> OK
A8: 7 | B8: Amulette de cuir | C8: Commun | D8: 10 | G8: p1 = armure ajoutée | H8: =$D8 -> 10 | I8: =$D8 -> 10 | J8: =$D8 -> 10 | K8: =Modèle!$D$2*INDEX(Drops!$E$14:$E$17,MATCH(C8,Drops!$A$14:$A$17,0)) -> 10 | L8: =I8/K8 -> 1 | M8: =J8/H8 -> 1 | N8: =IF(ABS(L8-1)>0.2,IF(L8<0.8,"Faible","Fort"),IF(OR(M8<0.67,M8>1.5),"Dérive","OK")) -> OK
A9: 8 | B9: Aimant de poche | C9: Commun | D9: 0.4 | E9: 0.12 | G9: p1 = rayon de ramassage ; p2 = XP gagnée | H9: =100*$D9*Modèle!$C$39+100*$E9*Modèle!$C$37 -> 10.2 | I9: =100*$D9*Modèle!$D$39+100*$E9*Modèle!$D$37 -> 10.2 | J9: =100*$D9*Modèle!$E$39+100*$E9*Modèle!$E$37 -> 10.2 | K9: =Modèle!$D$2*INDEX(Drops!$E$14:$E$17,MATCH(C9,Drops!$A$14:$A$17,0)) -> 10 | L9: =I9/K9 -> 1.02 | M9: =J9/H9 -> 1 | N9: =IF(ABS(L9-1)>0.2,IF(L9<0.8,"Faible","Fort"),IF(OR(M9<0.67,M9>1.5),"Dérive","OK")) -> OK
A10: 9 | B10: Sifflet de chasse | C10: Commun | D10: 0.22 | G10: p1 = vitesse d'attaque ajoutée | H10: =100*$D10*Modèle!$C$8 -> 9.5135135 | I10: =100*$D10*Modèle!$D$8 -> 9.5135135 | J10: =100*$D10*Modèle!$E$8 -> 9.5135135 | K10: =Modèle!$D$2*INDEX(Drops!$E$14:$E$17,MATCH(C10,Drops!$A$14:$A$17,0)) -> 10 | L10: =I10/K10 -> 0.95135135 | M10: =J10/H10 -> 1 | N10: =IF(ABS(L10-1)>0.2,IF(L10<0.8,"Faible","Fort"),IF(OR(M10<0.67,M10>1.5),"Dérive","OK")) -> OK
A11: 10 | B11: Étincelle | C11: Commun | D11: 0.18 | E11: 1 | G11: p1 = chance de proc ; p2 = dégâts de la brûlure en part du coup | H11: =100*$D11*$E11*Modèle!$C$25 -> 10.08 | I11: =100*$D11*$E11*Modèle!$D$25 -> 10.08 | J11: =100*$D11*$E11*Modèle!$E$25 -> 10.08 | K11: =Modèle!$D$2*INDEX(Drops!$E$14:$E$17,MATCH(C11,Drops!$A$14:$A$17,0)) -> 10 | L11: =I11/K11 -> 1.008 | M11: =J11/H11 -> 1 | N11: =IF(ABS(L11-1)>0.2,IF(L11<0.8,"Faible","Fort"),IF(OR(M11<0.67,M11>1.5),"Dérive","OK")) -> OK
A12: 11 | B12: Flocon | C12: Commun | D12: 0.22 | E12: 0.8 | G12: p1 = chance de proc ; p2 = équivalent en dégâts du ralentissement (30 % / 1,5 s = 0,8) | H12: =100*$D12*$E12*Modèle!$C$25 -> 9.856 | I12: =100*$D12*$E12*Modèle!$D$25 -> 9.856 | J12: =100*$D12*$E12*Modèle!$E$25 -> 9.856 | K12: =Modèle!$D$2*INDEX(Drops!$E$14:$E$17,MATCH(C12,Drops!$A$14:$A$17,0)) -> 10 | L12: =I12/K12 -> 0.9856 | M12: =J12/H12 -> 1 | N12: =IF(ABS(L12-1)>0.2,IF(L12<0.8,"Faible","Fort"),IF(OR(M12<0.67,M12>1.5),"Dérive","OK")) -> OK
A13: 12 | B13: Fiole verte | C13: Commun | D13: 0.18 | E13: 0.8 | G13: p1 = chance de proc ; p2 = dégâts d'un cumul (20 %/s x 4 s = 0,8) | H13: =100*$D13*$E13*Modèle!$C$26 -> 10.08 | I13: =100*$D13*$E13*Modèle!$D$26 -> 10.08 | J13: =100*$D13*$E13*Modèle!$E$26 -> 10.08 | K13: =Modèle!$D$2*INDEX(Drops!$E$14:$E$17,MATCH(C13,Drops!$A$14:$A$17,0)) -> 10 | L13: =I13/K13 -> 1.008 | M13: =J13/H13 -> 1 | N13: =IF(ABS(L13-1)>0.2,IF(L13<0.8,"Faible","Fort"),IF(OR(M13<0.67,M13>1.5),"Dérive","OK")) -> OK
A14: 13 | B14: Pavois fêlé | C14: Commun | D14: 0.09 | G14: p1 = réduction des dégâts reçus | H14: =100*(1/(1-$D14)-1) -> 9.8901099 | I14: =100*(1/(1-$D14)-1) -> 9.8901099 | J14: =100*(1/(1-$D14)-1) -> 9.8901099 | K14: =Modèle!$D$2*INDEX(Drops!$E$14:$E$17,MATCH(C14,Drops!$A$14:$A$17,0)) -> 10 | L14: =I14/K14 -> 0.98901099 | M14: =J14/H14 -> 1 | N14: =IF(ABS(L14-1)>0.2,IF(L14<0.8,"Faible","Fort"),IF(OR(M14<0.67,M14>1.5),"Dérive","OK")) -> OK
A15: 14 | B15: Cœur de mousse | C15: Commun | D15: 0.0045 | G15: p1 = part des PV max rendue par seconde | H15: =100*$D15*Modèle!$C$16/Modèle!$C$18 -> 10.227273 | I15: =100*$D15*Modèle!$D$16/Modèle!$D$18 -> 10.227273 | J15: =100*$D15*Modèle!$E$16/Modèle!$E$18 -> 10.227273 | K15: =Modèle!$D$2*INDEX(Drops!$E$14:$E$17,MATCH(C15,Drops!$A$14:$A$17,0)) -> 10 | L15: =I15/K15 -> 1.0227273 | M15: =J15/H15 -> 1 | N15: =IF(ABS(L15-1)>0.2,IF(L15<0.8,"Faible","Fort"),IF(OR(M15<0.67,M15>1.5),"Dérive","OK")) -> OK
A16: 15 | B16: Pièce porte-bonheur | C16: Commun | D16: 0.0005 | E16: 0.25 | G16: p1 = part des PV max rendue par pièce ; p2 = or gagné | H16: =100*$D16*Modèle!$C$16*Modèle!$C$24/Modèle!$C$18+100*$E16*Modèle!$C$38 -> 10.068182 | I16: =100*$D16*Modèle!$D$16*Modèle!$D$24/Modèle!$D$18+100*$E16*Modèle!$D$38 -> 10.068182 | J16: =100*$D16*Modèle!$E$16*Modèle!$E$24/Modèle!$E$18+100*$E16*Modèle!$E$38 -> 10.068182 | K16: =Modèle!$D$2*INDEX(Drops!$E$14:$E$17,MATCH(C16,Drops!$A$14:$A$17,0)) -> 10 | L16: =I16/K16 -> 1.0068182 | M16: =J16/H16 -> 1 | N16: =IF(ABS(L16-1)>0.2,IF(L16<0.8,"Faible","Fort"),IF(OR(M16<0.67,M16>1.5),"Dérive","OK")) -> OK
A17: 16 | B17: Éclat d'expérience | C17: Commun | D17: 0.15 | G17: p1 = XP gagnée | H17: =100*$D17*Modèle!$C$37 -> 9 | I17: =100*$D17*Modèle!$D$37 -> 9 | J17: =100*$D17*Modèle!$E$37 -> 9 | K17: =Modèle!$D$2*INDEX(Drops!$E$14:$E$17,MATCH(C17,Drops!$A$14:$A$17,0)) -> 10 | L17: =I17/K17 -> 0.9 | M17: =J17/H17 -> 1 | N17: =IF(ABS(L17-1)>0.2,IF(L17<0.8,"Faible","Fort"),IF(OR(M17<0.67,M17>1.5),"Dérive","OK")) -> OK
A18: 17 | B18: Plume d'empenne | C18: Commun | D18: 0.3 | E18: 0.12 | G18: p1 = vitesse de projectile ; p2 = portée | H18: =100*(Modèle!$C$40*$D18+Modèle!$C$41*$E18) -> 9.9 | I18: =100*(Modèle!$D$40*$D18+Modèle!$D$41*$E18) -> 9.9 | J18: =100*(Modèle!$E$40*$D18+Modèle!$E$41*$E18) -> 9.9 | K18: =Modèle!$D$2*INDEX(Drops!$E$14:$E$17,MATCH(C18,Drops!$A$14:$A$17,0)) -> 10 | L18: =I18/K18 -> 0.99 | M18: =J18/H18 -> 1 | N18: =IF(ABS(L18-1)>0.2,IF(L18<0.8,"Faible","Fort"),IF(OR(M18<0.67,M18>1.5),"Dérive","OK")) -> OK
A19: 18 | B19: Cristal de feu | C19: Peu commun | D19: 0.4 | E19: 1 | G19: p1 = chance de proc ; p2 = dégâts de la brûlure en part du coup | H19: =100*$D19*$E19*Modèle!$C$25 -> 22.4 | I19: =100*$D19*$E19*Modèle!$D$25 -> 22.4 | J19: =100*$D19*$E19*Modèle!$E$25 -> 22.4 | K19: =Modèle!$D$2*INDEX(Drops!$E$14:$E$17,MATCH(C19,Drops!$A$14:$A$17,0)) -> 22 | L19: =I19/K19 -> 1.0181818 | M19: =J19/H19 -> 1 | N19: =IF(ABS(L19-1)>0.2,IF(L19<0.8,"Faible","Fort"),IF(OR(M19<0.67,M19>1.5),"Dérive","OK")) -> OK
A20: 19 | B20: Givre | C20: Peu commun | D20: 0.4 | E20: 1 | G20: p1 = chance de proc ; p2 = équivalent en dégâts (40 % / 2 s = 1,0) | H20: =100*$D20*$E20*Modèle!$C$25 -> 22.4 | I20: =100*$D20*$E20*Modèle!$D$25 -> 22.4 | J20: =100*$D20*$E20*Modèle!$E$25 -> 22.4 | K20: =Modèle!$D$2*INDEX(Drops!$E$14:$E$17,MATCH(C20,Drops!$A$14:$A$17,0)) -> 22 | L20: =I20/K20 -> 1.0181818 | M20: =J20/H20 -> 1 | N20: =IF(ABS(L20-1)>0.2,IF(L20<0.8,"Faible","Fort"),IF(OR(M20<0.67,M20>1.5),"Dérive","OK")) -> OK
A21: 20 | B21: Horloge arcanique | C21: Peu commun | D21: 0.2 | E21: 0.18 | G21: p1 = vitesse de recharge ; p2 = dégâts des sorts à recharge | H21: =100*($D21+$E21)*Modèle!$C$9 -> 21.567568 | I21: =100*($D21+$E21)*Modèle!$D$9 -> 21.567568 | J21: =100*($D21+$E21)*Modèle!$E$9 -> 21.567568 | K21: =Modèle!$D$2*INDEX(Drops!$E$14:$E$17,MATCH(C21,Drops!$A$14:$A$17,0)) -> 22 | L21: =I21/K21 -> 0.98034398 | M21: =J21/H21 -> 1 | N21: =IF(ABS(L21-1)>0.2,IF(L21<0.8,"Faible","Fort"),IF(OR(M21<0.67,M21>1.5),"Dérive","OK")) -> OK
A22: 21 | B22: Lame jumelle | C22: Peu commun | D22: 0.5 | G22: p1 = dégâts du sort 1 | H22: =100*$D22*Modèle!$C$8 -> 21.621622 | I22: =100*$D22*Modèle!$D$8 -> 21.621622 | J22: =100*$D22*Modèle!$E$8 -> 21.621622 | K22: =Modèle!$D$2*INDEX(Drops!$E$14:$E$17,MATCH(C22,Drops!$A$14:$A$17,0)) -> 22 | L22: =I22/K22 -> 0.98280098 | M22: =J22/H22 -> 1 | N22: =IF(ABS(L22-1)>0.2,IF(L22<0.8,"Faible","Fort"),IF(OR(M22<0.67,M22>1.5),"Dérive","OK")) -> OK
A23: 22 | B23: Venin concentré | C23: Peu commun | D23: 0.4 | E23: 0.8 | G23: p1 = chance de proc ; p2 = dégâts d'un cumul | H23: =100*$D23*$E23*Modèle!$C$26 -> 22.4 | I23: =100*$D23*$E23*Modèle!$D$26 -> 22.4 | J23: =100*$D23*$E23*Modèle!$E$26 -> 22.4 | K23: =Modèle!$D$2*INDEX(Drops!$E$14:$E$17,MATCH(C23,Drops!$A$14:$A$17,0)) -> 22 | L23: =I23/K23 -> 1.0181818 | M23: =J23/H23 -> 1 | N23: =IF(ABS(L23-1)>0.2,IF(L23<0.8,"Faible","Fort"),IF(OR(M23<0.67,M23>1.5),"Dérive","OK")) -> OK
A24: 23 | B24: Cape de brume | C24: Peu commun | D24: 0.18 | G24: p1 = chance d'esquive | H24: =100*(1/(1-$D24)-1) -> 21.95122 | I24: =100*(1/(1-$D24)-1) -> 21.95122 | J24: =100*(1/(1-$D24)-1) -> 21.95122 | K24: =Modèle!$D$2*INDEX(Drops!$E$14:$E$17,MATCH(C24,Drops!$A$14:$A$17,0)) -> 22 | L24: =I24/K24 -> 0.99778271 | M24: =J24/H24 -> 1 | N24: =IF(ABS(L24-1)>0.2,IF(L24<0.8,"Faible","Fort"),IF(OR(M24<0.67,M24>1.5),"Dérive","OK")) -> OK
A25: 24 | B25: Épines | C25: Peu commun | D25: 0.7 | G25: p1 = riposte en part des dégâts du sort 1 | H25: =100*$D25*Modèle!$C$20/Modèle!$C$7*(Modèle!$C$18/Modèle!$C$21) -> 19.978378 | I25: =100*$D25*Modèle!$D$20/Modèle!$D$7*(Modèle!$D$18/Modèle!$D$21) -> 24.236066 | J25: =100*$D25*Modèle!$E$20/Modèle!$E$7*(Modèle!$E$18/Modèle!$E$21) -> 24.627435 | K25: =Modèle!$D$2*INDEX(Drops!$E$14:$E$17,MATCH(C25,Drops!$A$14:$A$17,0)) -> 22 | L25: =I25/K25 -> 1.1016393 | M25: =J25/H25 -> 1.2327044 | N25: =IF(ABS(L25-1)>0.2,IF(L25<0.8,"Faible","Fort"),IF(OR(M25<0.67,M25>1.5),"Dérive","OK")) -> OK
A26: 25 | B26: Éclair en bouteille | C26: Peu commun | D26: 0.15 | E26: 3 | F26: 0.5 | G26: p1 = chance de proc ; p2 = nombre de cibles ; p3 = dégâts en part du coup | H26: =100*$D26*$E26*$F26 -> 22.5 | I26: =100*$D26*$E26*$F26 -> 22.5 | J26: =100*$D26*$E26*$F26 -> 22.5 | K26: =Modèle!$D$2*INDEX(Drops!$E$14:$E$17,MATCH(C26,Drops!$A$14:$A$17,0)) -> 22 | L26: =I26/K26 -> 1.0227273 | M26: =J26/H26 -> 1 | N26: =IF(ABS(L26-1)>0.2,IF(L26<0.8,"Faible","Fort"),IF(OR(M26<0.67,M26>1.5),"Dérive","OK")) -> OK
A27: 26 | B27: Rune de portée | C27: Peu commun | D27: 0.25 | E27: 0.15 | G27: p1 = surface de zone ; p2 = dégâts des sorts de zone | H27: =100*Modèle!$C$10*($D27*Modèle!$C$13*0.5+$E27*Modèle!$C$13) -> 22.297297 | I27: =100*Modèle!$D$10*($D27*Modèle!$D$13*0.5+$E27*Modèle!$D$13) -> 22.297297 | J27: =100*Modèle!$E$10*($D27*Modèle!$E$13*0.5+$E27*Modèle!$E$13) -> 22.297297 | K27: =Modèle!$D$2*INDEX(Drops!$E$14:$E$17,MATCH(C27,Drops!$A$14:$A$17,0)) -> 22 | L27: =I27/K27 -> 1.0135135 | M27: =J27/H27 -> 1 | N27: =IF(ABS(L27-1)>0.2,IF(L27<0.8,"Faible","Fort"),IF(OR(M27<0.67,M27>1.5),"Dérive","OK")) -> OK
A28: 27 | B28: Morsure vorace | C28: Peu commun | D28: 0.002 | G28: p1 = part des PV max rendue par kill | H28: =100*$D28*Modèle!$C$16*Modèle!$C$23/Modèle!$C$18 -> 22.727273 | I28: =100*$D28*Modèle!$D$16*Modèle!$D$23/Modèle!$D$18 -> 22.727273 | J28: =100*$D28*Modèle!$E$16*Modèle!$E$23/Modèle!$E$18 -> 22.727273 | K28: =Modèle!$D$2*INDEX(Drops!$E$14:$E$17,MATCH(C28,Drops!$A$14:$A$17,0)) -> 22 | L28: =I28/K28 -> 1.0330579 | M28: =J28/H28 -> 1 | N28: =IF(ABS(L28-1)>0.2,IF(L28<0.8,"Faible","Fort"),IF(OR(M28<0.67,M28>1.5),"Dérive","OK")) -> OK
A29: 28 | B29: Tonique vital | C29: Peu commun | D29: 0.15 | E29: 0.003 | G29: p1 = bonus de PV max ; p2 = part des PV max rendue par seconde | H29: =100*$D29+100*$E29*Modèle!$C$16/Modèle!$C$18 -> 21.818182 | I29: =100*$D29+100*$E29*Modèle!$D$16/Modèle!$D$18 -> 21.818182 | J29: =100*$D29+100*$E29*Modèle!$E$16/Modèle!$E$18 -> 21.818182 | K29: =Modèle!$D$2*INDEX(Drops!$E$14:$E$17,MATCH(C29,Drops!$A$14:$A$17,0)) -> 22 | L29: =I29/K29 -> 0.99173554 | M29: =J29/H29 -> 1 | N29: =IF(ABS(L29-1)>0.2,IF(L29<0.8,"Faible","Fort"),IF(OR(M29<0.67,M29>1.5),"Dérive","OK")) -> OK
A30: 29 | B30: Orbe de veille | C30: Peu commun | D30: 0.28 | G30: p1 = taille du bouclier en part des PV max | H30: =100*$D30*Modèle!$C$35 -> 22.4 | I30: =100*$D30*Modèle!$D$35 -> 22.4 | J30: =100*$D30*Modèle!$E$35 -> 22.4 | K30: =Modèle!$D$2*INDEX(Drops!$E$14:$E$17,MATCH(C30,Drops!$A$14:$A$17,0)) -> 22 | L30: =I30/K30 -> 1.0181818 | M30: =J30/H30 -> 1 | N30: =IF(ABS(L30-1)>0.2,IF(L30<0.8,"Faible","Fort"),IF(OR(M30<0.67,M30>1.5),"Dérive","OK")) -> OK
A31: 30 | B31: Sang chaud | C31: Peu commun | D31: 0.7 | G31: p1 = bonus de dégâts sous 50 % de PV | H31: =100*$D31*Modèle!$C$29 -> 21 | I31: =100*$D31*Modèle!$D$29 -> 21 | J31: =100*$D31*Modèle!$E$29 -> 21 | K31: =Modèle!$D$2*INDEX(Drops!$E$14:$E$17,MATCH(C31,Drops!$A$14:$A$17,0)) -> 22 | L31: =I31/K31 -> 0.95454545 | M31: =J31/H31 -> 1 | N31: =IF(ABS(L31-1)>0.2,IF(L31<0.8,"Faible","Fort"),IF(OR(M31<0.67,M31>1.5),"Dérive","OK")) -> OK
A32: 31 | B32: Marque du chasseur | C32: Peu commun | D32: 0.45 | G32: p1 = bonus de dégâts aux élites et boss | H32: =100*$D32*Modèle!$C$33 -> 22.5 | I32: =100*$D32*Modèle!$D$33 -> 22.5 | J32: =100*$D32*Modèle!$E$33 -> 22.5 | K32: =Modèle!$D$2*INDEX(Drops!$E$14:$E$17,MATCH(C32,Drops!$A$14:$A$17,0)) -> 22 | L32: =I32/K32 -> 1.0227273 | M32: =J32/H32 -> 1 | N32: =IF(ABS(L32-1)>0.2,IF(L32<0.8,"Faible","Fort"),IF(OR(M32<0.67,M32>1.5),"Dérive","OK")) -> OK
A33: 32 | B33: Carquois affûté | C33: Peu commun | D33: 0.3 | E33: 0.3 | G33: p1 = vitesse d'attaque ; p2 = vitesse de projectile | H33: =100*$D33*Modèle!$C$8+100*Modèle!$C$40*$E33 -> 20.472973 | I33: =100*$D33*Modèle!$D$8+100*Modèle!$D$40*$E33 -> 20.472973 | J33: =100*$D33*Modèle!$E$8+100*Modèle!$E$40*$E33 -> 20.472973 | K33: =Modèle!$D$2*INDEX(Drops!$E$14:$E$17,MATCH(C33,Drops!$A$14:$A$17,0)) -> 22 | L33: =I33/K33 -> 0.93058968 | M33: =J33/H33 -> 1 | N33: =IF(ABS(L33-1)>0.2,IF(L33<0.8,"Faible","Fort"),IF(OR(M33<0.67,M33>1.5),"Dérive","OK")) -> OK
A34: 33 | B34: Pointe perforante | C34: Peu commun | D34: 0.7 | G34: p1 = dégâts sur la cible traversée | H34: =100*Modèle!$C$8*$D34*Modèle!$C$27 -> 24.216216 | I34: =100*Modèle!$D$8*$D34*Modèle!$D$27 -> 24.216216 | J34: =100*Modèle!$E$8*$D34*Modèle!$E$27 -> 24.216216 | K34: =Modèle!$D$2*INDEX(Drops!$E$14:$E$17,MATCH(C34,Drops!$A$14:$A$17,0)) -> 22 | L34: =I34/K34 -> 1.1007371 | M34: =J34/H34 -> 1 | N34: =IF(ABS(L34-1)>0.2,IF(L34<0.8,"Faible","Fort"),IF(OR(M34<0.67,M34>1.5),"Dérive","OK")) -> OK
A35: 34 | B35: Aimant d'âme | C35: Rare | D35: 0.8 | E35: 3 | F35: 25 | G35: p1 = bonus de dégâts ; p2 = durée (s) ; p3 = kills entre deux déclenchements | H35: =100*$D35*MIN(1,$E35*Modèle!$C$23/$F35)+3 -> 51 | I35: =100*$D35*MIN(1,$E35*Modèle!$D$23/$F35)+3 -> 51 | J35: =100*$D35*MIN(1,$E35*Modèle!$E$23/$F35)+3 -> 51 | K35: =Modèle!$D$2*INDEX(Drops!$E$14:$E$17,MATCH(C35,Drops!$A$14:$A$17,0)) -> 50 | L35: =I35/K35 -> 1.02 | M35: =J35/H35 -> 1 | N35: =IF(ABS(L35-1)>0.2,IF(L35<0.8,"Faible","Fort"),IF(OR(M35<0.67,M35>1.5),"Dérive","OK")) -> OK
A36: 35 | B36: Chronomètre brisé | C36: Rare | D36: 0.7 | E36: 0.5 | G36: p1 = vitesse de recharge ; p2 = secondes rendues par élite | H36: =100*($D36+$E36*Modèle!$C$22)*Modèle!$C$9 -> 43.135135 | I36: =100*($D36+$E36*Modèle!$D$22)*Modèle!$D$9 -> 47.959459 | J36: =100*($D36+$E36*Modèle!$E$22)*Modèle!$E$9 -> 53.635135 | K36: =Modèle!$D$2*INDEX(Drops!$E$14:$E$17,MATCH(C36,Drops!$A$14:$A$17,0)) -> 50 | L36: =I36/K36 -> 0.95918919 | M36: =J36/H36 -> 1.2434211 | N36: =IF(ABS(L36-1)>0.2,IF(L36<0.8,"Faible","Fort"),IF(OR(M36<0.67,M36>1.5),"Dérive","OK")) -> OK
A37: 36 | B37: Tempête de braises | C37: Rare | D37: 0.3 | E37: 4 | G37: p1 = part des PV max du monstre ; p2 = ennemis touchés | H37: =100*Modèle!$C$31*$D37*$E37 -> 48 | I37: =100*Modèle!$D$31*$D37*$E37 -> 48 | J37: =100*Modèle!$E$31*$D37*$E37 -> 48 | K37: =Modèle!$D$2*INDEX(Drops!$E$14:$E$17,MATCH(C37,Drops!$A$14:$A$17,0)) -> 50 | L37: =I37/K37 -> 0.96 | M37: =J37/H37 -> 1 | N37: =IF(ABS(L37-1)>0.2,IF(L37<0.8,"Faible","Fort"),IF(OR(M37<0.67,M37>1.5),"Dérive","OK")) -> OK
A38: 37 | B38: Cœur de glace | C38: Rare | D38: 0.75 | G38: p1 = bonus de dégâts sur cibles ralenties | H38: =100*$D38*Modèle!$C$30 -> 48.75 | I38: =100*$D38*Modèle!$D$30 -> 48.75 | J38: =100*$D38*Modèle!$E$30 -> 48.75 | K38: =Modèle!$D$2*INDEX(Drops!$E$14:$E$17,MATCH(C38,Drops!$A$14:$A$17,0)) -> 50 | L38: =I38/K38 -> 0.975 | M38: =J38/H38 -> 1 | N38: =IF(ABS(L38-1)>0.2,IF(L38<0.8,"Faible","Fort"),IF(OR(M38<0.67,M38>1.5),"Dérive","OK")) -> OK
A39: 38 | B39: Peste vivante | C39: Rare | D39: 0.25 | E39: 4 | G39: p1 = part des PV max du monstre ; p2 = ennemis touchés | H39: =100*Modèle!$C$32*$D39*$E39+5 -> 45 | I39: =100*Modèle!$D$32*$D39*$E39+5 -> 45 | J39: =100*Modèle!$E$32*$D39*$E39+5 -> 45 | K39: =Modèle!$D$2*INDEX(Drops!$E$14:$E$17,MATCH(C39,Drops!$A$14:$A$17,0)) -> 50 | L39: =I39/K39 -> 0.9 | M39: =J39/H39 -> 1 | N39: =IF(ABS(L39-1)>0.2,IF(L39<0.8,"Faible","Fort"),IF(OR(M39<0.67,M39>1.5),"Dérive","OK")) -> OK
A40: 39 | B40: Œil du prédateur | C40: Rare | D40: 0.25 | E40: 3 | G40: p1 = chance de crit ajoutée ; p2 = multiplicateur de crit | H40: =100*((1+(Modèle!$C$14+$D40)*($E40-1))/(1+Modèle!$C$14*(Modèle!$C$15-1))-1) -> 52.380952 | I40: =100*((1+(Modèle!$D$14+$D40)*($E40-1))/(1+Modèle!$D$14*(Modèle!$D$15-1))-1) -> 52.380952 | J40: =100*((1+(Modèle!$E$14+$D40)*($E40-1))/(1+Modèle!$E$14*(Modèle!$E$15-1))-1) -> 52.380952 | K40: =Modèle!$D$2*INDEX(Drops!$E$14:$E$17,MATCH(C40,Drops!$A$14:$A$17,0)) -> 50 | L40: =I40/K40 -> 1.047619 | M40: =J40/H40 -> 1 | N40: =IF(ABS(L40-1)>0.2,IF(L40<0.8,"Faible","Fort"),IF(OR(M40<0.67,M40>1.5),"Dérive","OK")) -> OK
...

Sheet Modèle
A1: Code | B1: Paramètre du modèle | C1: 2:30 | D1: 5:00 (référence) | E1: 7:30 | F1: Source / hypothèse
A2: U | B2: Valeur d'un item Commun (points) | C2: =D2 -> 10 | D2: 10 | E2: =D2 -> 10 | F2: Calibré sur le simulateur v3 : 21 items achetés avant 7:30 = +474 % de puissance pour ≈ 49 poids de qualité, soit ≈ 9,7 points par poids ; arrondi à 10 pour garder les cibles 10 / 22 / 50 / 120
A3: COEF_AUTO | B3: Coef de DPS du sort 1 (0,8 toutes les 0,6 s) | C3: =0.8/0.6 -> 1.3333333 | D3: =0.8/0.6 -> 1.3333333 | E3: =0.8/0.6 -> 1.3333333 | F3: Maths_Scaling.md, section 10
A4: COEF_MONO | B4: Coef de DPS du sort mono-cible (6 toutes les 8 s) | C4: =6/8 -> 0.75 | D4: =6/8 -> 0.75 | E4: =6/8 -> 0.75 | F4: Maths_Scaling.md, section 10
A5: COEF_ZONE | B5: Coef de DPS du sort de zone (3 toutes les 6 s) | C5: =3/6 -> 0.5 | D5: =3/6 -> 0.5 | E5: =3/6 -> 0.5 | F5: Maths_Scaling.md, section 10
A6: COEF_ULT | B6: Coef de DPS de l'ultime (10 toutes les 20 s) | C6: =10/20 -> 0.5 | D6: =10/20 -> 0.5 | E6: =10/20 -> 0.5 | F6: Maths_Scaling.md, section 10
A7: COEFTOT | B7: Coef de DPS total mono-cible | C7: =C3+C4+C5+C6 -> 3.0833333 | D7: =D3+D4+D5+D6 -> 3.0833333 | E7: =E3+E4+E5+E6 -> 3.0833333 | F7: Somme des 4 lignes ci-dessus
A8: SA | B8: Part du DPS venant du sort 1 | C8: =C3/C7 -> 0.43243243 | D8: =D3/D7 -> 0.43243243 | E8: =E3/E7 -> 0.43243243 | F8: Calcul
A9: SCD | B9: Part du DPS venant des sorts à recharge | C9: =1-C8 -> 0.56756757 | D9: =1-D8 -> 0.56756757 | E9: =1-E8 -> 0.56756757 | F9: Calcul
A10: SZ | B10: Part du DPS venant des sorts de zone (zone + ultime) | C10: =(C5+C6)/C7 -> 0.32432432 | D10: =(D5+D6)/D7 -> 0.32432432 | E10: =(E5+E6)/E7 -> 0.32432432 | F10: Calcul
A11: CW | B11: Poids des situations de foule dans la valeur d'un effet de zone | C11: =D11 -> 0.5 | D11: 0.5 | E11: =D11 -> 0.5 | F11: Hypothèse
A12: CROWD | B12: Nombre moyen d'ennemis touchés en foule | C12: =D12 -> 4 | D12: 4 | E12: =D12 -> 4 | F12: Hypothèse
A13: MIX | B13: Multiplicateur de valeur des effets de zone | C13: =(1-C11)+C11*C12 -> 2.5 | D13: =(1-D11)+D11*D12 -> 2.5 | E13: =(1-E11)+E11*E12 -> 2.5 | F13: Calcul
A14: P0 | B14: Chance de critique de base | C14: =D14 -> 0.05 | D14: 0.05 | E14: =D14 -> 0.05 | F14: Maths_Scaling.md, section 6
A15: M0 | B15: Multiplicateur de critique de base | C15: =D15 -> 2 | D15: 2 | E15: =D15 -> 2 | F15: Maths_Scaling.md, section 6
A16: PVREF | B16: PV max du joueur (niveaux 6, 10 et 14) | C16: 250 | D16: 370 | E16: 490 | F16: 100 + 30 x (L - 1), niveaux 6, 10 et 14 (simulateur v3, mode Moyen)
A17: INFRAC | B17: Dégâts subis par seconde, en part des PV max | C17: =D17 -> 0.044 | D17: 0.044 | E17: =D17 -> 0.044 | F17: Hypothèse à valider en playtest : ≈ 15 PV/s à 5:00
A18: DPSIN | B18: Dégâts subis moyens par seconde (PV/s) | C18: =C17*C16 -> 11 | D18: =D17*D16 -> 16.28 | E18: =E17*E16 -> 21.56 | F18: Calcul
A19: DPSREF | B19: DPS mono-cible du joueur | C19: 150 | D19: 368 | E19: 763 | F19: Simulateur v3 (Moyen, petits piliers sans charge, gros pilier 90 s)
A20: COEF_SHOT | B20: Coef d'un tir du sort 1 | C20: =D20 -> 0.8 | D20: 0.8 | E20: =D20 -> 0.8 | F20: Maths_Scaling.md, section 10
A21: HIT | B21: Dégâts d'un coup de contact tier 1 | C21: 10 | D21: 12.2 | E21: 15.9 | F21: 8 x (1 + 0,30 x (D - 1)) avec D = 1,74 / 2,87 / 4,29
A22: EKPS | B22: Élites tués par seconde | C22: 0.12 | D22: 0.29 | E22: 0.49 | F22: ≈ 0,63 x kills/s x P_élite (D = 1,74 / 2,87 / 4,29), à valider
A23: KPS | B23: Kills par seconde | C23: =D23 -> 5 | D23: 5 | E23: =D23 -> 5 | F23: Simulateur v3 : 5,2 à 4,8 kills/s
A24: CPS | B24: Pièces ramassées par seconde | C24: =D24 -> 6 | D24: 6 | E24: =D24 -> 6 | F24: ≈ kills/s x 1,2
A25: FB | B25: Efficacité des brûlures et ralentissements (non cumulables, dégâts perdus si le monstre meurt avant) | C25: =D25 -> 0.56 | D25: 0.56 | E25: =D25 -> 0.56 | F25: 0,7 (part qui arrive avant la mort) x 0,8 (saturation)
A26: FP | B26: Efficacité du poison par proc | C26: =D26 -> 0.7 | D26: 0.7 | E26: =D26 -> 0.7 | F26: Part des dégâts qui arrive avant la mort
A27: OV | B27: Part des tirs qui touchent un deuxième ennemi aligné | C27: =D27 -> 0.8 | D27: 0.8 | E27: =D27 -> 0.8 | F27: Hypothèse en foule dense
A28: UPMOVE | B28: Part du temps où le joueur se déplace | C28: =D28 -> 0.65 | D28: 0.65 | E28: =D28 -> 0.65 | F28: Hypothèse (style survivor-like)
A29: UPLOW | B29: Part du temps passé sous 50 % de PV | C29: =D29 -> 0.3 | D29: 0.3 | E29: =D29 -> 0.3 | F29: Hypothèse
A30: UPSLOW | B30: Part du temps où les cibles sont ralenties (avec items de ralentissement) | C30: =D30 -> 0.65 | D30: 0.65 | E30: =D30 -> 0.65 | F30: Hypothèse
A31: BURNF | B31: Part des monstres qui meurent en brûlant (avec items de feu) | C31: =D31 -> 0.4 | D31: 0.4 | E31: =D31 -> 0.4 | F31: Hypothèse
A32: POISF | B32: Part des monstres qui meurent empoisonnés (avec items de poison) | C32: =D32 -> 0.4 | D32: 0.4 | E32: =D32 -> 0.4 | F32: Hypothèse
A33: SHBIG | B33: Part des dégâts à infliger qui concerne élites et boss | C33: =D33 -> 0.5 | D33: 0.5 | E33: =D33 -> 0.5 | F33: Hypothèse
A34: SHDOT | B34: Part des dégâts subis venant de brûlures et de poisons | C34: =D34 -> 0.25 | D34: 0.25 | E34: =D34 -> 0.25 | F34: Hypothèse à 5:00 (élites à affixes + boss)
... A44: CDAVG | B44: Recharge moyenne des sorts à recharge (s) | C44: =D44 -> 11 | D44: 11 | E44: =D44 -> 11 | F44: Moyenne de 6, 8 et 20 s
A45: KILLS | B45: Kills cumulés | C45: 1039 | D45: 2046 | E45: 3013 | F45: Simulateur v3 (Moyen, petits piliers sans charge, gros pilier 90 s)
A46: CH5 | B46: Petits coffres sur lesquels la Chance agit | C46: =D46 -> 9 | D46: 9 | E46: =D46 -> 9 | F46: Simulateur v3 : ≈ 9 petits et grands coffres ouverts à 5:00 (≈ 25 sur la run)

Sheet Drops
A1: Table de drops (cellules en bleu = valeurs modifiables)
A3: 1. Qualité par type de coffre
A4: Coffre | B4: Commun | C4: Peu commun | D4: Rare | E4: Légendaire | F4: Total
A5: Petit (d100) | B5: 0.6 | C5: 0.32 | D5: 0.07 | E5: 0.01 | F5: =SUM(B5:E5) -> 1
A6: Large | B6: 0 | C6: 0.8 | D6: 0.2 | E6: 0 | F6: =SUM(B6:E6) -> 1
A7: Légendaire | B7: 0 | C7: 0 | D7: 0 | E7: 1 | F7: =SUM(B7:E7) -> 1
A8: Boss d'étage | B8: 0 | C8: 0 | D8: 0.9 | E8: 0.1 | F8: =SUM(B8:E8) -> 1
A10: Le total de chaque ligne doit faire 100 %. Chance (Luck) : chaque point relance le d100 du petit coffre et garde le meilleur résultat.
A12: 2. Chance d'apparition d'un item précis
A13: Qualité | B13: Taille de la table | C13: Chance par item dans la table | D13: Chance par item sur un petit coffre | E13: Puissance relative cible
A14: Commun | B14: =COUNTIF(Items!$C$2:$C$51,A14) -> 17 | C14: =1/B14 -> 0.058823529 | D14: =B$5*C14 -> 0.035294118 | E14: 1
A15: Peu commun | B15: =COUNTIF(Items!$C$2:$C$51,A15) -> 16 | C15: =1/B15 -> 0.0625 | D15: =C$5*C15 -> 0.02 | E15: 2.2
A16: Rare | B16: =COUNTIF(Items!$C$2:$C$51,A16) -> 11 | C16: =1/B16 -> 0.090909091 | D16: =D$5*C16 -> 0.0063636364 | E16: 5
A17: Légendaire | B17: =COUNTIF(Items!$C$2:$C$51,A17) -> 6 | C17: =1/B17 -> 0.16666667 | D17: =E$5*C17 -> 0.0016666667 | E17: 12
A19: 3. Protection contre la malchance (pity) sur les petits coffres
A20: Poids Rare+ de base (Rare + Légendaire) | D20: =D5+E5 -> 0.08
A21: Bonus par petit coffre sans Rare+ | D21: 0.02
A23: Nº du petit coffre | B23: Poids Rare+ avec pity | C23: Proba cumulée d'au moins un Rare+ (avec pity) | D23: Proba cumulée (sans pity)
A24: 1 | B24: =MIN(1,$D$20+$D$21*(A24-1)) -> 0.08 | C24: =B24 -> 0.08 | D24: =1-(1-$D$20)^A24 -> 0.08
A25: 2 | B25: =MIN(1,$D$20+$D$21*(A25-1)) -> 0.1 | C25: =1-(1-C24)*(1-B25) -> 0.172 | D25: =1-(1-$D$20)^A25 -> 0.1536
A26: 3 | B26: =MIN(1,$D$20+$D$21*(A26-1)) -> 0.12 | C26: =1-(1-C25)*(1-B26) -> 0.27136 | D26: =1-(1-$D$20)^A26 -> 0.221312
A27: 4 | B27: =MIN(1,$D$20+$D$21*(A27-1)) -> 0.14 | C27: =1-(1-C26)*(1-B27) -> 0.3733696 | D27: =1-(1-$D$20)^A27 -> 0.28360704
A28: 5 | B28: =MIN(1,$D$20+$D$21*(A28-1)) -> 0.16 | C28: =1-(1-C27)*(1-B28) -> 0.47363046 | D28: =1-(1-$D$20)^A28 -> 0.34091848
A29: 6 | B29: =MIN(1,$D$20+$D$21*(A29-1)) -> 0.18 | C29: =1-(1-C28)*(1-B29) -> 0.56837698 | D29: =1-(1-$D$20)^A29 -> 0.393645
A30: 7 | B30: =MIN(1,$D$20+$D$21*(A30-1)) -> 0.2 | C30: =1-(1-C29)*(1-B30) -> 0.65470158 | D30: =1-(1-$D$20)^A30 -> 0.4421534
A31: 8 | B31: =MIN(1,$D$20+$D$21*(A31-1)) -> 0.22 | C31: =1-(1-C30)*(1-B31) -> 0.73066724 | D31: =1-(1-$D$20)^A31 -> 0.48678113
A32: 9 | B32: =MIN(1,$D$20+$D$21*(A32-1)) -> 0.24 | C32: =1-(1-C31)*(1-B32) -> 0.7953071 | D32: =1-(1-$D$20)^A32 -> 0.52783864
A33: 10 | B33: =MIN(1,$D$20+$D$21*(A33-1)) -> 0.26 | C33: =1-(1-C32)*(1-B33) -> 0.84852725 | D33: =1-(1-$D$20)^A33 -> 0.56561155
A34: 11 | B34: =MIN(1,$D$20+$D$21*(A34-1)) -> 0.28 | C34: =1-(1-C33)*(1-B34) -> 0.89093962 | D34: =1-(1-$D$20)^A34 -> 0.60036262
A35: 12 | B35: =MIN(1,$D$20+$D$21*(A35-1)) -> 0.3 | C35: =1-(1-C34)*(1-B35) -> 0.92365774 | D35: =1-(1-$D$20)^A35 -> 0.63233361
A37: Lecture : à 9 petits coffres (un peu plus d'un étage), la probabilité d'avoir au moins un Rare+ passe d'environ 53 % à environ 79 % avec le pity.
A39: 4. Répartition attendue d'une run de 3 étages, mode Moyen (28 items : 19 petits + 5 larges + 3 boss d'étage + 1 légendaire)
A40: Source | B40: Nombre | C40: Commun | D40: Peu commun | E40: Rare | F40: Légendaire
A41: Petits coffres (sans pity) | B41: 19 | C41: =$B41*B5 -> 11.4 | D41: =$B41*C5 -> 6.08 | E41: =$B41*D5 -> 1.33 | F41: =$B41*E5 -> 0.19
A42: Coffres larges | B42: 5 | C42: =$B42*B6 -> 0 | D42: =$B42*C6 -> 4 | E42: =$B42*D6 -> 1 | F42: =$B42*E6 -> 0
A43: Boss d'étage (gratuit) | B43: 3 | C43: =$B43*B8 -> 0 | D43: =$B43*C8 -> 0 | E43: =$B43*D8 -> 2.7 | F43: =$B43*E8 -> 0.3
A44: Coffre légendaire (25 % des étages) | B44: 1 | C44: =$B44*B7 -> 0 | D44: =$B44*C7 -> 0 | E44: =$B44*D7 -> 0 | F44: =$B44*E7 -> 1
A45: Total attendu | B45: =SUM(B41:B44) -> 28 | C45: =SUM(C41:C44) -> 11.4 | D45: =SUM(D41:D44) -> 10.08 | E45: =SUM(E41:E44) -> 5.03 | F45: =SUM(F41:F44) -> 1.49
A46: Hors effet du pity et de la Chance, qui déplacent légèrement la répartition vers Rare et Légendaire.

Sheet Légende
A1: Légende
A3: Comment lire le classeur :
A4: - Items : le catalogue (texte, empilement, tags, chances de drop) avec la valeur et le ratio à la cible venant de l'onglet Audit.
A5: - Audit : chaque item converti en points de puissance (1 point = +1 % de DPS ou de PV effectifs) aux moments 2:30, 5:00 et 7:30, comparé à sa cible.
A6: - Modèle : les constantes du jeu (parts de DPS, PV, dégâts subis, élites, kills) utilisées par les formules. Les valeurs en bleu sont des entrées modifiables.
A7: - Drops : taux de drop par coffre, chance par item, pity, répartition attendue d'une run.
A9: Cellules à modifier pour équilibrer :
A10: - Audit, colonnes p1 à p3 (en bleu) : les paramètres de chaque item. Le verdict se met à jour (OK si le ratio est entre 0,8 et 1,2 et la dérive entre 0,67 et 1,5).
A11: - Si tu changes un paramètre, mets aussi à jour le texte de l'effet dans Items (le texte n'est pas relié aux paramètres).
A12: - Modèle (en bleu) et Drops (en bleu) : hypothèses globales, probabilités, puissance relative des qualités.
A14: Cible de puissance :
A15: - Un Commun vaut 10 points, un Peu commun 22, un Rare 50, un Légendaire 120 (poids 1 / 2,2 / 5 / 12).
... A32: - Les items qui dépendent d'une synergie (Tempête de braises, Peste vivante, Cœur de glace) sont valorisés en supposant que le joueur a des sources de brûlure, de poison ou de ralentissement.
